Workbook

Sheet Inputs
A1: ALHC model inputs (blue = hardcoded input; yellow = key assumption). $ in millions unless noted.
A3: Input | B3: Value | C3: Source / note
A4: price | B4: 8.28 | C4: Nasdaq close 16 Oct 2026 (Yahoo chart API; Google Finance)
A5: price_sep14 | B5: 12.94 | C5: Close 14 Sep 2026 (S&P Global via StockAnalysis; Yahoo)
A6: price_oct8 | B6: 8.71 | C6: Close 8 Oct 2026
A7: basic_shares | B7: 207.43515 | C7: Shares outstanding 27 Jul 2026, 10-Q cover (m)
A8: q3_rev_guide_mid | B8: 1310 | C8: Q3 2026 revenue guidance $1,300-1,320m (Q2 release)
A9: q3_gp_guide_mid | B9: 153 | C9: Q3 2026 adj. gross profit guidance $148-158m (Q2 call)
A10: q3_ebitda_guide_mid | B10: 25 | C10: Q3 2026 adj. EBITDA guidance $20-30m
A11: q3_members_mid | B11: 296.5 | C11: Q3 2026 membership guidance 295.5-297.5k
A12: fy26_rev_guide_mid | B12: 5210 | C12: FY2026 revenue guidance $5,195-5,225m
A13: fy26_gp_guide_mid | B13: 640 | C13: FY2026 adj. gross profit guidance $630-650m (Q2 call)
A14: fy26_ebitda_guide_mid | B14: 154 | C14: FY2026 adj. EBITDA guidance $145-163m
A15: fy26_members_mid | B15: 299.5 | C15: FY2026 membership guidance 298-301k
... A54: cost_persist | B54: 0.5 | C54: Author: share of H2-2026 MBR pressure that persists into 2027 (base)

Sheet MBR Bridge
A1: 2027 medical benefit ratio bridge (MBR = adjusted medical cost / revenue)
A3: Step | B3: Bear | C3: Base | D3: Bull | E3: How it is built
A4: 2026E MBR (model) | B4: =Model!$P$10 -> 0.87884574 | C4: =Model!$P$10 -> 0.87884574 | D4: =Model!$P$10 -> 0.87884574 | E4: My FY2026 estimate (Model sheet); guidance midpoint implies ~87.7%
A5: Members in year 1-2, 2026 | B5: =(1-Inputs!$B$48/(1+Inputs!$B$49))*(1+Inputs!$B$48/(1+Inputs!$B$49)) -> 0.55216932 | C5: =B5 -> 0.55216932 | D5: =B5 -> 0.55216932 | E5: Steady-state share at 31.5% growth, 88% retention: new + second-year members
A6: Members in year 1-2, 2027 | B6: =(1-Inputs!$B$48/(1+Inputs!$B$18))*(1+Inputs!$B$48/(1+Inputs!$B$18)) -> 0.44383798 | C6: =B6 -> 0.44383798 | D6: =B6 -> 0.44383798 | E6: Same at 2027 growth
A7: New vs mature MBR gap | B7: =(2*(Inputs!$B$51-Inputs!$B$50))/Inputs!$B$12 -> 0.092130518 | C7: =B7 -> 0.092130518 | D7: =B7 -> 0.092130518 | E7: From management's $880m vs $640m: half the book is new, so new-member GP is lower by 2x(880-640) per the whole book
A8: Maturity (mix) effect | B8: =0 -> 0 | C8: =-(B5-B6)*B7*Inputs!$B$52 -> -0.0049903116 | D8: =-(B5-B6)*B7 -> -0.0099806231 | E8: Fewer early-tenure members as growth slows; bear gives no credit, base half, bull full
A9: Rate vs cost trend | B9: =B4*((1+Inputs!$B$47+0.006)/(1+Inputs!$B$21)-1) -> 0.0079529763 | C9: =B4*((1+Inputs!$B$47)/(1+Inputs!$B$21)-1) -> 0.0029300439 | D9: =B4*((1+Inputs!$B$47)/(1+Inputs!$B$21)-1) -> 0.0029300439 | E9: Cost per member grows with CMS effective growth rate 5.33% vs revenue +4.98%; bear adds 0.6 pts of trend
A10: 2027 benefit design | B10: =0 -> 0 | C10: =Inputs!$B$53 -> -0.002 | D10: =Inputs!$B$53 -> -0.002 | E10: Bids filed June 2026: modest trims in the 2027 plan data
A11: H2-2026 cost pressure carried | B11: =(Model!$S$10-Model!$P$10) -> 0.0066433694 | C11: =(Model!$S$10-Model!$P$10)*Inputs!$B$54 -> 0.0033216847 | D11: =0 -> 0 | E11: H2-2026 MBR above full year: all of it persists (bear), half (base), none (bull)
A12: 2027E MBR | B12: =B4+B8+B9+B10+B11 -> 0.89344208 | C12: =C4+C8+C9+C10+C11 -> 0.87810715 | D12: =D4+D8+D9+D10+D11 -> 0.86979516

Sheet Model
A1: Alignment Healthcare quarterly model ($m unless noted; members in thousands)
A3: Line | B3: Note | C3: Q1'26A | D3: Q2'26A | E3: Q3'26E | F3: Q4'26E | G3: Q1'27E | H3: Q2'27E | I3: Q3'27E | J3: Q4'27E | K3: Q1'28E | L3: Q2'28E | M3: Q3'28E | N3: Q4'28E | P3: FY26 | Q3: FY27 | R3: FY28 | S3: H2-26
A5: Ending members (k) | B5: Q2 actual 294,100 (release); Q3/Q4 guidance midpoints; 2027-28 growth inputs | D5: 294.1 | E5: =Inputs!$B$11 -> 296.5 | F5: =Inputs!$B$15 -> 299.5 | G5: =F5*(1+Inputs!$B$18*Inputs!$B$20) -> 342.628 | H5: =G5+(F5*(1+Inputs!$B$18)-G5)/3 -> 346.222 | I5: =H5+(F5*(1+Inputs!$B$18)-G5)/3 -> 349.816 | J5: =F5*(1+Inputs!$B$18) -> 353.41 | K5: =J5*(1+Inputs!$B$19*Inputs!$B$20) -> 395.8192 | L5: =K5+(J5*(1+Inputs!$B$19)-K5)/3 -> 399.3533 | M5: =L5+(J5*(1+Inputs!$B$19)-K5)/3 -> 402.8874 | N5: =J5*(1+Inputs!$B$19) -> 406.4215 | P5: =F5 -> 299.5 | Q5: =J5 -> 353.41 | R5: =N5 -> 406.4215
A6: Average members (k) | B6: Average of quarter ends; Q1 = quarter end because the January step lands on 1 Jan | E6: =(D5+E5)/2 -> 295.3 | F6: =(E5+F5)/2 -> 298 | G6: =G5 -> 342.628 | H6: =(G5+H5)/2 -> 344.425 | I6: =(H5+I5)/2 -> 348.019 | J6: =(I5+J5)/2 -> 351.613 | K6: =K5 -> 395.8192 | L6: =(K5+L5)/2 -> 397.58625 | M6: =(L5+M5)/2 -> 401.12035 | N6: =(M5+N5)/2 -> 404.65445
A7: Revenue PMPM ($) | B7: 2026 from guidance; 2027 = H2-26 PMPM x (1 + 4.98%); 2028 = 2027 x (1 + rate28) | E7: =E8/(E6*3)*1000 -> 1478.7222 | F7: =F8/(F6*3)*1000 -> 1486.7673 | G7: =AVERAGE($E$7:$F$7)*(1+Inputs!$B$21) -> 1556.5855 | H7: =AVERAGE($E$7:$F$7)*(1+Inputs!$B$21) -> 1556.5855 | I7: =AVERAGE($E$7:$F$7)*(1+Inputs!$B$21) -> 1556.5855 | J7: =AVERAGE($E$7:$F$7)*(1+Inputs!$B$21) -> 1556.5855 | K7: =$G$7*(1+Inputs!$B$22) -> 1603.283 | L7: =$G$7*(1+Inputs!$B$22) -> 1603.283 | M7: =$G$7*(1+Inputs!$B$22) -> 1603.283 | N7: =$G$7*(1+Inputs!$B$22) -> 1603.283
A8: Revenue | B8: Q1/Q2 actual (10-Q); Q3 guidance midpoint; Q4 = FY guide less 9M | C8: 1235.197 | D8: 1335.633 | E8: =Inputs!$B$8 -> 1310 | F8: =Inputs!$B$12-C8-D8-E8 -> 1329.17 | G8: =G6*3*G7/1000 -> 1599.9893 | H8: =H6*3*H7/1000 -> 1608.3808 | I8: =I6*3*I7/1000 -> 1625.1639 | J8: =J6*3*J7/1000 -> 1641.9471 | K8: =K6*3*K7/1000 -> 1903.8306 | L8: =L6*3*L7/1000 -> 1912.3299 | M8: =M6*3*M7/1000 -> 1929.3283 | N8: =N6*3*N7/1000 -> 1946.3268 | P8: =SUM(C8:F8) -> 5210 | Q8: =SUM(G8:J8) -> 6475.4811 | R8: =SUM(K8:N8) -> 7691.8156 | S8: =SUM(E8:F8) -> 2639.17
A9: Adj. gross profit (actual/guide) | B9: Q1 = H1 approx $329m less Q2 $183m (Q2 call); Q2 reported | C9: 146 | D9: 183
A10: Adj. MBR | B10: 2027 quarters keep the 2026 seasonal shape around the bridge result; 2028 = 2027 + delta | C10: =1-C9/C8 -> 0.88180023 | D10: =1-D9/D8 -> 0.86298631 | E10: =Inputs!$B$16 -> 0.887 | F10: =Inputs!$B$17 -> 0.884 | G10: =C10-$P$10+'MBR Bridge'!$C$12 -> 0.88106165 | H10: =D10-$P$10+'MBR Bridge'!$C$12 -> 0.86224773 | I10: =E10-$P$10+'MBR Bridge'!$C$12 -> 0.88626142 | J10: =F10-$P$10+'MBR Bridge'!$C$12 -> 0.88326142 | K10: =G10-$Q$10+$Q$10+Inputs!$B$25 -> 0.88106165 | L10: =H10-$Q$10+$Q$10+Inputs!$B$25 -> 0.86224773 | M10: =I10-$Q$10+$Q$10+Inputs!$B$25 -> 0.88626142 | N10: =J10-$Q$10+$Q$10+Inputs!$B$25 -> 0.88326142 | P10: =1-P12/P8 -> 0.87884574 | Q10: =1-Q12/Q8 -> 0.87825142 | R10: =1-R12/R8 -> 0.87824503 | S10: =1-S12/S8 -> 0.8854891
A11: Adj. medical cost | C11: =C8-C9 -> 1089.197 | D11: =D8-D9 -> 1152.633 | E11: =E8*E10 -> 1161.97 | F11: =F8*F10 -> 1174.9863 | G11: =G8*G10 -> 1409.6892 | H11: =H8*H10 -> 1386.8227 | I11: =I8*I10 -> 1440.3201 | J11: =J8*J10 -> 1450.2685 | K11: =K8*K10 -> 1677.3921 | L11: =L8*L10 -> 1648.9021 | ... N11: =N8*N10 -> 1719.1154 | P11: =SUM(C11:F11) -> 4578.7863 | Q11: =SUM(G11:J11) -> 5687.1005 | R11: =SUM(K11:N11) -> 6755.2989 | S11: =SUM(E11:F11) -> 2336.9563
A12: Adj. gross profit | C12: =C8-C11 -> 146 | D12: =D8-D11 -> 183 | E12: =E8-E11 -> 148.03 | F12: =F8-F11 -> 154.18372 | G12: =G8-G11 -> 190.30009 | H12: =H8-H11 -> 221.55811 | I12: =I8-I11 -> 184.84384 | J12: =J8-J11 -> 191.67857 | ... N12: =N8-N11 -> 227.21144 | P12: =SUM(C12:F12) -> 631.21372 | Q12: =SUM(G12:J12) -> 788.38062 | R12: =SUM(K12:N12) -> 936.51676 | S12: =SUM(E12:F12) -> 302.21372
A13: Adj. SG&A | B13: Actual = GP less EBITDA; Q3 guide-implied; Q4 = FY guide-implied less 9M; then % of revenue | C13: =C12-C14 -> 108.149 | D13: =D12-D14 -> 114.855 | E13: =Inputs!$B$9-Inputs!$B$10 -> 128 | F13: =(Inputs!$B$13-Inputs!$B$14)-C13-D13-E13 -> 134.996 | G13: =G8*Inputs!$B$23 -> 143.99904 | H13: =H8*Inputs!$B$23 -> 144.75428 | I13: =I8*Inputs!$B$23 -> 146.26476 | J13: =J8*Inputs!$B$23 -> 147.77523 | K13: =K8*Inputs!$B$24 -> 167.53709 | L13: =L8*Inputs!$B$24 -> 168.28503 | M13: =M8*Inputs!$B$24 -> 169.78089 | N13: =N8*Inputs!$B$24 -> 171.27676 | P13: =SUM(C13:F13) -> 486 | Q13: =SUM(G13:J13) -> 582.7933 | R13: =SUM(K13:N13) -> 676.87978 | S13: =SUM(E13:F13) -> 262.996
A14: Adj. EBITDA before stars | B14: Q1/Q2 reported (Q2 release: H1 $106.0m, Q2 $68.1m) | C14: 37.851 | D14: 68.145 | E14: =E12-E13 -> 20.03 | F14: =F12-F13 -> 19.18772 | G14: =G12-G13 -> 46.301053 | H14: =H12-H13 -> 76.803834 | I14: =I12-I13 -> 38.579089 | J14: =J12-J13 -> 43.903337 | K14: =K12-K13 -> 58.901381 | L14: =L12-L13 -> 95.142749 | ... N14: =N12-N13 -> 55.934675 | P14: =SUM(C14:F14) -> 145.21372 | Q14: =SUM(G14:J14) -> 205.58731 | R14: =SUM(K14:N14) -> 259.63698 | S14: =SUM(E14:F14) -> 39.21772
A15: Expected 2028 stars hit | B15: Blend of paths, lawsuit odds 25% (value_v8.py) | C15: 0 | D15: 0 | E15: 0 | F15: 0 | G15: 0 | H15: 0 | I15: 0 | J15: 0 | K15: =-Inputs!$B$26/4 -> -9.65 | L15: =-Inputs!$B$26/4 -> -9.65 | M15: =-Inputs!$B$26/4 -> -9.65 | N15: =-Inputs!$B$26/4 -> -9.65 | P15: =SUM(C15:F15) -> 0 | Q15: =SUM(G15:J15) -> 0 | R15: =SUM(K15:N15) -> -38.6 | S15: =SUM(E15:F15) -> 0
A16: Adj. EBITDA | C16: =C14+C15 -> 37.851 | D16: =D14+D15 -> 68.145 | E16: =E14+E15 -> 20.03 | F16: =F14+F15 -> 19.18772 | G16: =G14+G15 -> 46.301053 | H16: =H14+H15 -> 76.803834 | I16: =I14+I15 -> 38.579089 | J16: =J14+J15 -> 43.903337 | ... N16: =N14+N15 -> 46.284675 | P16: =SUM(C16:F16) -> 145.21372 | Q16: =SUM(G16:J16) -> 205.58731 | R16: =SUM(K16:N16) -> 221.03698 | S16: =SUM(E16:F16) -> 39.21772
A17: D&A | B17: Q1/Q2 10-Q | C17: 7.839 | D17: 7.854 | E17: =D17 -> 7.854 | F17: =D17 -> 7.854 | G17: =$F$17*(1+Inputs!$B$28) -> 8.6394 | H17: =$F$17*(1+Inputs!$B$28) -> 8.6394 | I17: =$F$17*(1+Inputs!$B$28) -> 8.6394 | J17: =$F$17*(1+Inputs!$B$28) -> 8.6394 | K17: =$G$17*(1+Inputs!$B$28) -> 9.50334 | L17: =$G$17*(1+Inputs!$B$28) -> 9.50334 | M17: =$G$17*(1+Inputs!$B$28) -> 9.50334 | N17: =$G$17*(1+Inputs!$B$28) -> 9.50334 | P17: =SUM(C17:F17) -> 31.401 | Q17: =SUM(G17:J17) -> 34.5576 | R17: =SUM(K17:N17) -> 38.01336 | S17: =SUM(E17:F17) -> 15.708
A18: Interest expense | B18: Q1/Q2 10-Q; revolver undrawn | C18: 4.062 | D18: 4.275 | E18: =$D$18 -> 4.275 | F18: =$D$18 -> 4.275 | G18: =$D$18 -> 4.275 | H18: =$D$18 -> 4.275 | I18: =$D$18 -> 4.275 | J18: =$D$18 -> 4.275 | K18: =$D$18 -> 4.275 | L18: =$D$18 -> 4.275 | ... N18: =$D$18 -> 4.275 | P18: =SUM(C18:F18) -> 16.887 | Q18: =SUM(G18:J18) -> 17.1 | R18: =SUM(K18:N18) -> 17.1 | S18: =SUM(E18:F18) -> 8.55
A19: Stock-based compensation | B19: Q1/Q2 10-Q (H1 $32.2m) | C19: 14.019 | D19: 18.174 | E19: =D19 -> 18.174 | F19: =D19 -> 18.174 | G19: =$D$19*(1+Inputs!$B$29) -> 19.0827 | H19: =$D$19*(1+Inputs!$B$29) -> 19.0827 | I19: =$D$19*(1+Inputs!$B$29) -> 19.0827 | J19: =$D$19*(1+Inputs!$B$29) -> 19.0827 | K19: =$G$19*(1+Inputs!$B$29) -> 20.036835 | L19: =$G$19*(1+Inputs!$B$29) -> 20.036835 | M19: =$G$19*(1+Inputs!$B$29) -> 20.036835 | N19: =$G$19*(1+Inputs!$B$29) -> 20.036835 | P19: =SUM(C19:F19) -> 68.541 | Q19: =SUM(G19:J19) -> 76.3308 | R19: =SUM(K19:N19) -> 80.14734 | S19: =SUM(E19:F19) -> 36.348
A20: Pre-tax income (approx. GAAP) | B20: Q1/Q2 reported pre-tax (10-Q) | C20: 11.441 | D20: 37.826 | E20: =E16-E17-E18-E19 -> -10.273 | F20: =F16-F17-F18-F19 -> -11.11528 | G20: =G16-G17-G18-G19 -> 14.303953 | H20: =H16-H17-H18-H19 -> 44.806734 | I20: =I16-I17-I18-I19 -> 6.5819892 | J20: =J16-J17-J18-J19 -> 11.906237 | K20: =K16-K17-K18-K19 -> 15.436206 | L20: =L16-L17-L18-L19 -> 51.677574 | ... N20: =N16-N17-N18-N19 -> 12.4695 | P20: =SUM(C20:F20) -> 27.87872 | Q20: =SUM(G20:J20) -> 77.598914 | R20: =SUM(K20:N20) -> 85.776283 | S20: =SUM(E20:F20) -> -21.38828
A21: Income tax | C21: 0.025 | D21: 1.266 | E21: =MAX(0,E20)*Inputs!$B$31 -> 0 | F21: =MAX(0,F20)*Inputs!$B$31 -> 0 | G21: =MAX(0,G20)*Inputs!$B$31 -> 0.42911859 | H21: =MAX(0,H20)*Inputs!$B$31 -> 1.344202 | I21: =MAX(0,I20)*Inputs!$B$31 -> 0.19745968 | J21: =MAX(0,J20)*Inputs!$B$31 -> 0.35718712 | K21: =MAX(0,K20)*Inputs!$B$31 -> 0.46308619 | L21: =MAX(0,L20)*Inputs!$B$31 -> 1.5503272 | ... N21: =MAX(0,N20)*Inputs!$B$31 -> 0.374085 | P21: =SUM(C21:F21) -> 1.291 | Q21: =SUM(G21:J21) -> 2.3279674 | R21: =SUM(K21:N21) -> 2.5732885 | S21: =SUM(E21:F21) -> 0
A22: Net income | C22: =C20-C21 -> 11.416 | D22: =D20-D21 -> 36.56 | E22: =E20-E21 -> -10.273 | F22: =F20-F21 -> -11.11528 | G22: =G20-G21 -> 13.874835 | H22: =H20-H21 -> 43.462532 | I22: =I20-I21 -> 6.3845295 | J22: =J20-J21 -> 11.54905 | ... N22: =N20-N21 -> 12.095415 | P22: =SUM(C22:F22) -> 26.58772 | Q22: =SUM(G22:J22) -> 75.270946 | R22: =SUM(K22:N22) -> 83.202994 | S22: =SUM(E22:F22) -> -21.38828
A23: Adj. net income (EBITDA - D&A - interest) | B23: Matches the consensus adj. EPS definition used in ops_model.py | C23: =C16-C17-C18 -> 25.95 | D23: =D16-D17-D18 -> 56.016 | E23: =E16-E17-E18 -> 7.901 | F23: =F16-F17-F18 -> 7.05872 | G23: =G16-G17-G18 -> 33.386653 | H23: =H16-H17-H18 -> 63.889434 | I23: =I16-I17-I18 -> 25.664689 | J23: =J16-J17-J18 -> 30.988937 | ... N23: =N16-N17-N18 -> 32.506335 | P23: =SUM(C23:F23) -> 96.92572 | Q23: =SUM(G23:J23) -> 153.92971 | R23: =SUM(K23:N23) -> 165.92362 | S23: =SUM(E23:F23) -> 14.95972
A24: Diluted shares (m) | B24: Q2 10-Q 215.0m; Q1 approx. | C24: 213.7 | D24: 215.024 | E24: =D24*(1+Inputs!$B$30) -> 216.31414 | F24: =E24*(1+Inputs!$B$30) -> 217.61203 | G24: =F24*(1+Inputs!$B$30) -> 218.9177 | H24: =G24*(1+Inputs!$B$30) -> 220.23121 | I24: =H24*(1+Inputs!$B$30) -> 221.55259 | J24: =I24*(1+Inputs!$B$30) -> 222.88191 | K24: =J24*(1+Inputs!$B$30) -> 224.2192 | L24: =K24*(1+Inputs!$B$30) -> 225.56452 | ... N24: =M24*(1+Inputs!$B$30) -> 228.27941 | P24: =AVERAGE(C24:F24) -> 215.66254 | Q24: =AVERAGE(G24:J24) -> 220.89585 | R24: =AVERAGE(K24:N24) -> 226.24526
A25: Adj. EPS ($) | C25: =C23/C24 -> 0.12143191 | D25: =D23/D24 -> 0.26051045 | E25: =E23/E24 -> 0.036525582 | F25: =F23/F24 -> 0.032437177 | G25: =G23/G24 -> 0.15250778 | H25: =H23/H24 -> 0.29010164 | I25: =I23/I24 -> 0.11584017 | J25: =J23/J24 -> 0.13903747 | ... N25: =N23/N24 -> 0.14239714 | P25: =P23/P24 -> 0.44943233 | Q25: =Q23/Q24 -> 0.69684293 | R25: =R23/R24 -> 0.73337945
A26: GAAP EPS ($) | C26: =C22/C24 -> 0.053420683 | D26: =D22/D24 -> 0.17002753 | E26: =E22/E24 -> -0.047491116 | F26: =F22/F24 -> -0.051078426 | G26: =G22/G24 -> 0.063379226 | H26: =H22/H24 -> 0.19734956 | I26: =I22/I24 -> 0.028817218 | J26: =J22/J24 -> 0.051816903 | ... N26: =N22/N24 -> 0.052985134 | P26: =P22/P24 -> 0.1232839 | Q26: =Q22/Q24 -> 0.3407531 | R26: =R22/R24 -> 0.36775575
A28: Balance sheet (quarter end)
A29: Cash and equivalents | B29: 30 Jun 2026 10-Q; then cash flow | D29: 693.453 | E29: =D29+E63 -> 712.95255 | F29: =E29+F63 -> 720.22292 | G29: =F29+G63 -> 791.49027 | H29: =G29+H63 -> 839.42866 | I29: =H29+I63 -> 888.14119 | J29: =I29+J63 -> 918.90379 | K29: =J29+K63 -> 991.91784 | L29: =K29+L63 -> 1045.3198 | ... N29: =M29+N63 -> 1132.0546 | P29: =F29 -> 720.22292 | Q29: =J29 -> 918.90379 | R29: =N29 -> 1132.0546
A30: Accounts receivable | D30: 296.893 | E30: =E8*Inputs!$B$33 -> 291.19513 | F30: =F8*Inputs!$B$33 -> 295.45636 | G30: =G8*Inputs!$B$33 -> 355.6558 | H30: =H8*Inputs!$B$33 -> 357.52113 | I30: =I8*Inputs!$B$33 -> 361.25178 | J30: =J8*Inputs!$B$33 -> 364.98244 | K30: =K8*Inputs!$B$33 -> 423.19558 | L30: =L8*Inputs!$B$33 -> 425.08485 | ... N30: =N8*Inputs!$B$33 -> 432.64191 | P30: =F30 -> 295.45636 | Q30: =J30 -> 364.98244 | R30: =N30 -> 432.64191
A31: Investments, current | D31: 8.258 | E31: =D31 -> 8.258 | F31: =E31 -> 8.258 | G31: =F31 -> 8.258 | H31: =G31 -> 8.258 | I31: =H31 -> 8.258 | J31: =I31 -> 8.258 | K31: =J31 -> 8.258 | L31: =K31 -> 8.258 | ... N31: =M31 -> 8.258 | P31: =F31 -> 8.258 | Q31: =J31 -> 8.258 | R31: =N31 -> 8.258
A32: Prepaid and other current | D32: 161.845 | E32: =E8*Inputs!$B$34 -> 158.73893 | F32: =F8*Inputs!$B$34 -> 161.06185 | G32: =G8*Inputs!$B$34 -> 193.87831 | H32: =H8*Inputs!$B$34 -> 194.89515 | I32: =I8*Inputs!$B$34 -> 196.92884 | J32: =J8*Inputs!$B$34 -> 198.96253 | K32: =K8*Inputs!$B$34 -> 230.69621 | L32: =L8*Inputs!$B$34 -> 231.7261 | ... N32: =N8*Inputs!$B$34 -> 235.84567 | P32: =F32 -> 161.06185 | Q32: =J32 -> 198.96253 | R32: =N32 -> 235.84567
A33: Property and equipment | D33: 66.211 | E33: =D33+Inputs!$B$37-E17 -> 67.357 | F33: =E33+Inputs!$B$37-F17 -> 68.503 | G33: =F33+Inputs!$B$37-G17 -> 68.8636 | H33: =G33+Inputs!$B$37-H17 -> 69.2242 | I33: =H33+Inputs!$B$37-I17 -> 69.5848 | J33: =I33+Inputs!$B$37-J17 -> 69.9454 | K33: =J33+Inputs!$B$37-K17 -> 69.44206 | L33: =K33+Inputs!$B$37-L17 -> 68.93872 | ... N33: =M33+Inputs!$B$37-N17 -> 67.93204 | P33: =F33 -> 68.503 | Q33: =J33 -> 69.9454 | R33: =N33 -> 67.93204
A34: Right-of-use, goodwill, intangibles, other | D34: 52.378 | E34: =D34 -> 52.378 | F34: =E34 -> 52.378 | G34: =F34 -> 52.378 | H34: =G34 -> 52.378 | I34: =H34 -> 52.378 | J34: =I34 -> 52.378 | K34: =J34 -> 52.378 | L34: =K34 -> 52.378 | ... N34: =M34 -> 52.378 | P34: =F34 -> 52.378 | Q34: =J34 -> 52.378 | R34: =N34 -> 52.378
A35: Total assets | D35: =SUM(D29:D34) -> 1279.038 | E35: =SUM(E29:E34) -> 1290.8796 | F35: =SUM(F29:F34) -> 1305.8801 | G35: =SUM(G29:G34) -> 1470.524 | H35: =SUM(H29:H34) -> 1521.7051 | I35: =SUM(I29:I34) -> 1576.5426 | J35: =SUM(J29:J34) -> 1613.4302 | K35: =SUM(K29:K34) -> 1775.8877 | ... N35: =SUM(N29:N34) -> 1929.1102 | P35: =F35 -> 1305.8801 | Q35: =J35 -> 1613.4302 | R35: =N35 -> 1929.1102
A37: Medical expenses payable | B37: Days claims payable held at 48.3 | D37: 612.748 | E37: =E11/91*Inputs!$B$36 -> 616.73792 | F37: =F11/91*Inputs!$B$36 -> 623.64656 | G37: =G11/91*Inputs!$B$36 -> 748.21965 | H37: =H11/91*Inputs!$B$36 -> 736.08283 | I37: =I11/91*Inputs!$B$36 -> 764.47759 | J37: =J11/91*Inputs!$B$36 -> 769.75788 | K37: =K11/91*Inputs!$B$36 -> 890.30813 | L37: =L11/91*Inputs!$B$36 -> 875.18649 | ... N37: =N11/91*Inputs!$B$36 -> 912.45356 | P37: =F37 -> 623.64656 | Q37: =J37 -> 769.75788 | R37: =N37 -> 912.45356
A38: Accounts payable and accrued | D38: 32.27 | E38: =E8*Inputs!$B$35 -> 31.650685 | F38: =F8*Inputs!$B$35 -> 32.113849 | G38: =G8*Inputs!$B$35 -> 38.657067 | H38: =H8*Inputs!$B$35 -> 38.859814 | I38: =I8*Inputs!$B$35 -> 39.265308 | J38: =J8*Inputs!$B$35 -> 39.670801 | K38: =K8*Inputs!$B$35 -> 45.998125 | L38: =L8*Inputs!$B$35 -> 46.203474 | ... N38: =N8*Inputs!$B$35 -> 47.024869 | P38: =F38 -> 32.113849 | Q38: =J38 -> 39.670801 | R38: =N38 -> 47.024869
A39: Accrued compensation and leases | D39: 44.833 | E39: =D39 -> 44.833 | F39: =E39 -> 44.833 | G39: =F39 -> 44.833 | H39: =G39 -> 44.833 | I39: =H39 -> 44.833 | J39: =I39 -> 44.833 | K39: =J39 -> 44.833 | L39: =K39 -> 44.833 | ... N39: =M39 -> 44.833 | P39: =F39 -> 44.833 | Q39: =J39 -> 44.833 | R39: =N39 -> 44.833
A40: Convertible notes (carrying) | B40: Accretes to $330m face | D40: 324.056 | E40: =MIN(Inputs!$B$41,D40+Inputs!$B$38) -> 324.626 | F40: =MIN(Inputs!$B$41,E40+Inputs!$B$38) -> 325.196 | G40: =MIN(Inputs!$B$41,F40+Inputs!$B$38) -> 325.766 | H40: =MIN(Inputs!$B$41,G40+Inputs!$B$38) -> 326.336 | I40: =MIN(Inputs!$B$41,H40+Inputs!$B$38) -> 326.906 | J40: =MIN(Inputs!$B$41,I40+Inputs!$B$38) -> 327.476 | K40: =MIN(Inputs!$B$41,J40+Inputs!$B$38) -> 328.046 | L40: =MIN(Inputs!$B$41,K40+Inputs!$B$38) -> 328.616 | ... N40: =MIN(Inputs!$B$41,M40+Inputs!$B$38) -> 329.756 | P40: =F40 -> 325.196 | Q40: =J40 -> 327.476 | R40: =N40 -> 329.756
A41: Total liabilities | D41: =SUM(D37:D40) -> 1013.907 | E41: =SUM(E37:E40) -> 1017.8476 | F41: =SUM(F37:F40) -> 1025.7894 | G41: =SUM(G37:G40) -> 1157.4757 | H41: =SUM(H37:H40) -> 1146.1116 | I41: =SUM(I37:I40) -> 1175.4819 | J41: =SUM(J37:J40) -> 1181.7377 | K41: =SUM(K37:K40) -> 1309.1853 | ... N41: =SUM(N37:N40) -> 1334.0674 | P41: =F41 -> 1025.7894 | Q41: =J41 -> 1181.7377 | R41: =N41 -> 1334.0674
A42: Stockholders' equity | B42: Prior + net income + stock comp | D42: 265.131 | E42: =D42+E22+E19 -> 273.032 | F42: =E42+F22+F19 -> 280.09072 | G42: =F42+G22+G19 -> 313.04825 | H42: =G42+H22+H19 -> 375.59349 | I42: =H42+I22+I19 -> 401.06072 | J42: =I42+J22+J19 -> 431.69247 | K42: =J42+K22+K19 -> 466.70242 | L42: =K42+L22+L19 -> 536.8665 | ... N42: =M42+N22+N19 -> 595.0428 | P42: =F42 -> 280.09072 | Q42: =J42 -> 431.69247 | R42: =N42 -> 595.0428
A43: Total liabilities and equity | D43: =D41+D42 -> 1279.038 | E43: =E41+E42 -> 1290.8796 | F43: =F41+F42 -> 1305.8801 | G43: =G41+G42 -> 1470.524 | H43: =H41+H42 -> 1521.7051 | I43: =I41+I42 -> 1576.5426 | J43: =J41+J42 -> 1613.4302 | K43: =K41+K42 -> 1775.8877 | ... N43: =N41+N42 -> 1929.1102 | P43: =F43 -> 1305.8801 | Q43: =J43 -> 1613.4302 | R43: =N43 -> 1929.1102
A44: Check (assets - L&E) | B44: Must be zero | D44: =ROUND(D35-D43,6) -> 0 | E44: =ROUND(E35-E43,6) -> 0 | F44: =ROUND(F35-F43,6) -> 0 | G44: =ROUND(G35-G43,6) -> 0 | H44: =ROUND(H35-H43,6) -> 0 | I44: =ROUND(I35-I43,6) -> 0 | J44: =ROUND(J35-J43,6) -> 0 | K44: =ROUND(K35-K43,6) -> 0 | ... N44: =ROUND(N35-N43,6) -> 0 | P44: =F44 -> 0 | Q44: =J44 -> 0 | R44: =N44 -> 0
...

Sheet Statutory Capital
A1: California tangible net equity (TNE) check, Knox-Keene formula as described in the Q2 2026 10-Q, note 11
A2: Required = 150% of the largest of $1m; 2% of first $150m of annualized premium + 1% above; 8% of first $150m of non-capitated health care spend + 4% above. Per-plan amounts are not disclosed. The 10-K gives the aggregate: regulatory capital $268.5m vs a $116.1m minimum at 31 Dec 2025 (data/regulatory_capital.csv).
A4: Line | B4: FY26E | C4: FY27E | D4: FY28E | E4: Note
A5: CA annualized premium | B5: =Model!P8*Inputs!$B$44 -> 4063.8 | C5: =Model!Q8*Inputs!$B$44 -> 5050.8753 | D5: =Model!R8*Inputs!$B$44 -> 5999.6162 | E5: Revenue x CA share
A6: CA medical spend | B6: =Model!P11*Inputs!$B$44 -> 3571.4533 | C6: =Model!Q11*Inputs!$B$44 -> 4435.9384 | D6: =Model!R11*Inputs!$B$44 -> 5269.1331
A7: Required: premium test | B7: =0.02*MIN(150,B5)+0.01*MAX(0,B5-150) -> 42.138 | C7: =0.02*MIN(150,C5)+0.01*MAX(0,C5-150) -> 52.008753 | D7: =0.02*MIN(150,D5)+0.01*MAX(0,D5-150) -> 61.496162 | E7: 2% of first $150m + 1% above
A8: Required: spend test, 0% capitated | B8: =0.08*MIN(150,B6*(1-Inputs!$B$45))+0.04*MAX(0,B6*(1-Inputs!$B$45)-150) -> 148.85813 | C8: =0.08*MIN(150,C6*(1-Inputs!$B$45))+0.04*MAX(0,C6*(1-Inputs!$B$45)-150) -> 183.43754 | D8: =0.08*MIN(150,D6*(1-Inputs!$B$45))+0.04*MAX(0,D6*(1-Inputs!$B$45)-150) -> 216.76533 | E8: 8% / 4%, no capitation
A9: Required: spend test, 50% capitated | B9: =0.08*MIN(150,B6*(1-Inputs!$B$46))+0.04*MAX(0,B6*(1-Inputs!$B$46)-150) -> 77.429066 | C9: =0.08*MIN(150,C6*(1-Inputs!$B$46))+0.04*MAX(0,C6*(1-Inputs!$B$46)-150) -> 94.718768 | D9: =0.08*MIN(150,D6*(1-Inputs!$B$46))+0.04*MAX(0,D6*(1-Inputs!$B$46)-150) -> 111.38266 | E9: 8% / 4% on half the spend
A10: Required TNE (150%), low case | B10: =1.5*MAX(1,B7,B9) -> 116.1436 | C10: =1.5*MAX(1,C7,C9) -> 142.07815 | D10: =1.5*MAX(1,D7,D9) -> 167.07399 | E10: Max of premium test and 50%-capitated spend test
A11: Required TNE (150%), high case | B11: =1.5*MAX(1,B7,B8) -> 223.2872 | C11: =1.5*MAX(1,C7,C8) -> 275.1563 | D11: =1.5*MAX(1,D7,D8) -> 325.14799 | E11: Max of premium test and 0%-capitated spend test
A12: Regulatory capital (filed YE25, plus net income) | B12: =268.515+Model!P22 -> 295.10272 | C12: =B12+Model!Q22 -> 370.37367 | D12: =C12+Model!R22 -> 453.57666 | E12: 10-K FY2025: $268.5m at 31 Dec 2025, rolled forward with consolidated net income (all subsidiaries, all states)
A13: Headroom, low requirement | B13: =B12-B10 -> 178.95912 | C13: =C12-C10 -> 228.29551 | D13: =D12-D10 -> 286.50267
A14: Headroom, high requirement | B14: =B12-B11 -> 71.815522 | C14: =C12-C11 -> 95.217362 | D14: =D12-D11 -> 128.42867
A15: Minimum, all states, at the 2025 ratio to revenue | B15: =116.09/3948.719*Model!P8 -> 153.17091 | C15: =116.09/3948.719*Model!Q8 -> 190.37531 | D15: =116.09/3948.719*Model!R8 -> 226.13482 | E15: 10-K FY2025: $116.1m minimum on $3,948.7m revenue
A16: Cover vs that minimum (x) | B16: =B12/B15 -> 1.9266237 | C16: =C12/C15 -> 1.9454921 | D16: =D12/D15 -> 2.0057798 | E16: Filed 2.31x at YE25 (2.08x YE24)

Sheet Valuation
A1: SUPERSEDED (v8 method, kept for the record). The price target is built in scripts/valuation_v10.py. Peer data Yahoo Finance, 16 Oct 2026 closes and 17 Oct consensus.
A3: Ticker | B3: Price 16 Oct | C3: Price 14 Sep | D3: Shares (m) | E3: EV ($m) | F3: EBITDA TTM ($m) | G3: EPS 2026E | H3: EPS 2027E | I3: Fwd P/E | J3: Fwd EBITDA 2027 ($m) | K3: Fwd EV/EBITDA | L3: P/E at 14 Sep | M3: EV/EBITDA at 14 Sep
A4: UNH | B4: 401.43 | C4: 383.55 | D4: 897.59485 | E4: 409287.85 | F4: 28903 | G4: 20.51338 | H4: 23.22918 | I4: =B4/H4 -> 17.281282 | J4: =F4+(H4-G4)*D4/(1-Inputs!$B$32) -> 32110.484 | K4: =E4/J4 -> 12.746237 | L4: =C4/H4 -> 16.51156 | M4: =(E4+(C4-B4)*D4)/J4 -> 12.246432
A5: HUM | B5: 413.16 | C5: 407.02 | D5: 120.08031 | E5: 40549.38 | F5: 3596 | G5: 9.15913 | H5: 17.08832 | I5: =B5/H5 -> 24.177918 | J5: =F5+(H5-G5)*D5/(1-Inputs!$B$32) -> 4848.8152 | K5: =E5/J5 -> 8.3627398 | L5: =C5/H5 -> 23.818608 | M5: =(E5+(C5-B5)*D5)/J5 -> 8.2106835
A6: ELV | B6: 428.26 | C6: 424.24 | D6: 216.86929 | E6: 86545.441 | F6: 8323.9997 | G6: 27.24418 | H6: 29.60006 | I6: =B6/H6 -> 14.468214 | J6: =F6+(H6-G6)*D6/(1-Inputs!$B$32) -> 8996.2603 | K6: =E6/J6 -> 9.6201575 | L6: =C6/H6 -> 14.332403 | M6: =(E6+(C6-B6)*D6)/J6 -> 9.5232489
A7: CVS | B7: 92.36 | C7: 95.55 | D7: 1278.9704 | E7: 180670.71 | F7: 16679.999 | G7: 8.04287 | H7: 8.53519 | I7: =B7/H7 -> 10.821083 | J7: =F7+(H7-G7)*D7/(1-Inputs!$B$32) -> 17508.503 | K7: =E7/J7 -> 10.319027 | L7: =C7/H7 -> 11.19483 | M7: =(E7+(C7-B7)*D7)/J7 -> 10.552051
A8: CNC | B8: 69.16 | C8: 69.41 | D8: 493.995 | E8: 23307.694 | F8: 4606.0001 | G8: 4.88462 | H8: 5.34776 | I8: =B8/H8 -> 12.932518 | J8: =F8+(H8-G8)*D8/(1-Inputs!$B$32) -> 4907.0381 | K8: =E8/J8 -> 4.7498498 | L8: =C8/H8 -> 12.979266 | M8: =(E8+(C8-B8)*D8)/J8 -> 4.7750175
A9: MOH | B9: 207.36 | C9: 214.07 | D9: 52.2 | E9: 5862.1921 | F9: 390 | G9: 5.24983 | H9: 8.55097 | I9: =B9/H9 -> 24.24988 | J9: =F9+(H9-G9)*D9/(1-Inputs!$B$32) -> 616.73619 | K9: =E9/J9 -> 9.5051858 | L9: =C9/H9 -> 25.034587 | M9: =(E9+(C9-B9)*D9)/J9 -> 10.073114
A10: CI | B10: 302.3 | C10: 290.05 | D10: 264.24049 | E10: 104790.9 | F10: 12758 | G10: 30.51015 | H10: 33.48462 | I10: =B10/H10 -> 9.0280254 | J10: =F10+(H10-G10)*D10/(1-Inputs!$B$32) -> 13792.178 | K10: =E10/J10 -> 7.5978502 | L10: =C10/H10 -> 8.6621858 | M10: =(E10+(C10-B10)*D10)/J10 -> 7.3631559
A11: Median, all seven | I11: =MEDIAN(I4:I10) -> 14.468214 | K11: =MEDIAN(K4:K10) -> 9.5051858 | L11: =MEDIAN(L4:L10) -> 14.332403 | M11: =MEDIAN(M4:M10) -> 9.5232489
A12: Median ex HUM, MOH (trough 2026 EPS) | I12: =MEDIAN(I4,I6,I7,I8,I10) -> 12.932518 | K12: =MEDIAN(K4,K6,K7,K8,K10) -> 9.6201575 | L12: =MEDIAN(L4,L6,L7,L8,L10) -> 12.979266 | M12: =MEDIAN(M4,M6,M7,M8,M10) -> 9.5232489
A13: Fwd EBITDA 2027 = TTM EBITDA + (EPS27 - EPS26) x shares / (1 - 24%): an approximation; Yahoo does not publish forward EBITDA. Sep 14 multiples use today's consensus EPS.
A15: ALHC price target (house method)
A16: 2027E revenue | B16: =Model!Q8 -> 6475.4811
A17: 2027E MBR | B17: =Model!Q10 -> 0.87825142
A18: 2027E adj. SG&A ratio | B18: =Inputs!$B$23 -> 0.09
A19: 2027E adj. EBITDA | B19: =Model!Q16 -> 205.58731
A20: 2027E D&A + interest | B20: =Model!Q17+Model!Q18 -> 51.6576
A21: 2027E adj. net income | B21: =Model!Q23 -> 153.92971
A22: Diluted shares 2027 (m) | B22: =Model!Q24 -> 220.89585
A23: Peer forward P/E (median) | B23: =I11 -> 14.468214
A24: Peer forward EV/EBITDA (median) | B24: =K11 -> 9.5051858
A25: NOL value per share | B25: =Inputs!$B$42*0.21*Inputs!$B$43/B22 -> 0.4633879
A26: Parent net debt | B26: =Inputs!$B$41-Inputs!$B$39 -> 194.6
A27: P/E value | B27: =B23*B21*(1-Inputs!$B$32)/B22+B25 -> 8.1257631
A28: EV/EBITDA value | B28: =(B24*B19-B26)/B22 -> 7.9654986
A29: Less stars cost | B29: =-Inputs!$B$27 -> -0.937
A30: 12-month price target | B30: =AVERAGE(B27,B28)+B29 -> 7.1086309
A31: Upside / (downside) | B31: =B30/Inputs!$B$4-1 -> -0.1414697
A33: Price-implied 2027 MBR
A34: Now ($8.28, full stars cost, today's multiples) | B34: =1-B18-((2*(Inputs!$B$4+Inputs!$B$27)-B25+I11*B20*(1-Inputs!$B$32)/B22+B26/B22)/(I11*(1-Inputs!$B$32)/B22+K11/B22))/B16 -> 0.87435323
A35: 14 Sep ($12.94, 31% of stars cost, 14 Sep multiples) | B35: =1-B18-((2*(Inputs!$B$5+0.31*Inputs!$B$27)-B25+L11*B20*(1-Inputs!$B$32)/B22+B26/B22)/(L11*(1-Inputs!$B$32)/B22+M11/B22))/B16 -> 0.86083276
A36: Change (points of MBR) | B36: =B34-B35 -> 0.013520472
A39: Target sensitivity: forward P/E (rows) x 2027 MBR (columns); EV/EBITDA leg at the peer median
B40: 0.87 | C40: 0.875 | D40: 0.879 | E40: 0.885 | F40: 0.89 | G40: 0.895
A41: 12 | B41: =AVERAGE($A41*(($B$16*(1-B$40-$B$18))-$B$20)*(1-Inputs!$B$32)/$B$22+$B$25,($K$11*($B$16*(1-B$40-$B$18))-$B$26)/$B$22)-Inputs!$B$27 -> 8.7076462 | C41: =AVERAGE($A41*(($B$16*(1-C$40-$B$18))-$B$20)*(1-Inputs!$B$32)/$B$22+$B$25,($K$11*($B$16*(1-C$40-$B$18))-$B$26)/$B$22)-Inputs!$B$27 -> 7.34267 | D41: =AVERAGE($A41*(($B$16*(1-D$40-$B$18))-$B$20)*(1-Inputs!$B$32)/$B$22+$B$25,($K$11*($B$16*(1-D$40-$B$18))-$B$26)/$B$22)-Inputs!$B$27 -> 6.250689 | E41: =AVERAGE($A41*(($B$16*(1-E$40-$B$18))-$B$20)*(1-Inputs!$B$32)/$B$22+$B$25,($K$11*($B$16*(1-E$40-$B$18))-$B$26)/$B$22)-Inputs!$B$27 -> 4.6127174 | F41: =AVERAGE($A41*(($B$16*(1-F$40-$B$18))-$B$20)*(1-Inputs!$B$32)/$B$22+$B$25,($K$11*($B$16*(1-F$40-$B$18))-$B$26)/$B$22)-Inputs!$B$27 -> 3.2477412 | G41: =AVERAGE($A41*(($B$16*(1-G$40-$B$18))-$B$20)*(1-Inputs!$B$32)/$B$22+$B$25,($K$11*($B$16*(1-G$40-$B$18))-$B$26)/$B$22)-Inputs!$B$27 -> 1.8827649
A42: 13 | B42: =AVERAGE($A42*(($B$16*(1-B$40-$B$18))-$B$20)*(1-Inputs!$B$32)/$B$22+$B$25,($K$11*($B$16*(1-B$40-$B$18))-$B$26)/$B$22)-Inputs!$B$27 -> 9.0643638 | C42: =AVERAGE($A42*(($B$16*(1-C$40-$B$18))-$B$20)*(1-Inputs!$B$32)/$B$22+$B$25,($K$11*($B$16*(1-C$40-$B$18))-$B$26)/$B$22)-Inputs!$B$27 -> 7.6436897 | D42: =AVERAGE($A42*(($B$16*(1-D$40-$B$18))-$B$20)*(1-Inputs!$B$32)/$B$22+$B$25,($K$11*($B$16*(1-D$40-$B$18))-$B$26)/$B$22)-Inputs!$B$27 -> 6.5071504 | E42: =AVERAGE($A42*(($B$16*(1-E$40-$B$18))-$B$20)*(1-Inputs!$B$32)/$B$22+$B$25,($K$11*($B$16*(1-E$40-$B$18))-$B$26)/$B$22)-Inputs!$B$27 -> 4.8023416 | F42: =AVERAGE($A42*(($B$16*(1-F$40-$B$18))-$B$20)*(1-Inputs!$B$32)/$B$22+$B$25,($K$11*($B$16*(1-F$40-$B$18))-$B$26)/$B$22)-Inputs!$B$27 -> 3.3816675 | G42: =AVERAGE($A42*(($B$16*(1-G$40-$B$18))-$B$20)*(1-Inputs!$B$32)/$B$22+$B$25,($K$11*($B$16*(1-G$40-$B$18))-$B$26)/$B$22)-Inputs!$B$27 -> 1.9609934
A43: 14.5 | B43: =AVERAGE($A43*(($B$16*(1-B$40-$B$18))-$B$20)*(1-Inputs!$B$32)/$B$22+$B$25,($K$11*($B$16*(1-B$40-$B$18))-$B$26)/$B$22)-Inputs!$B$27 -> 9.5994401 | C43: =AVERAGE($A43*(($B$16*(1-C$40-$B$18))-$B$20)*(1-Inputs!$B$32)/$B$22+$B$25,($K$11*($B$16*(1-C$40-$B$18))-$B$26)/$B$22)-Inputs!$B$27 -> 8.0952193 | D43: =AVERAGE($A43*(($B$16*(1-D$40-$B$18))-$B$20)*(1-Inputs!$B$32)/$B$22+$B$25,($K$11*($B$16*(1-D$40-$B$18))-$B$26)/$B$22)-Inputs!$B$27 -> 6.8918427 | E43: =AVERAGE($A43*(($B$16*(1-E$40-$B$18))-$B$20)*(1-Inputs!$B$32)/$B$22+$B$25,($K$11*($B$16*(1-E$40-$B$18))-$B$26)/$B$22)-Inputs!$B$27 -> 5.0867777 | F43: =AVERAGE($A43*(($B$16*(1-F$40-$B$18))-$B$20)*(1-Inputs!$B$32)/$B$22+$B$25,($K$11*($B$16*(1-F$40-$B$18))-$B$26)/$B$22)-Inputs!$B$27 -> 3.582557 | G43: =AVERAGE($A43*(($B$16*(1-G$40-$B$18))-$B$20)*(1-Inputs!$B$32)/$B$22+$B$25,($K$11*($B$16*(1-G$40-$B$18))-$B$26)/$B$22)-Inputs!$B$27 -> 2.0783362
A44: 16 | B44: =AVERAGE($A44*(($B$16*(1-B$40-$B$18))-$B$20)*(1-Inputs!$B$32)/$B$22+$B$25,($K$11*($B$16*(1-B$40-$B$18))-$B$26)/$B$22)-Inputs!$B$27 -> 10.134516 | C44: =AVERAGE($A44*(($B$16*(1-C$40-$B$18))-$B$20)*(1-Inputs!$B$32)/$B$22+$B$25,($K$11*($B$16*(1-C$40-$B$18))-$B$26)/$B$22)-Inputs!$B$27 -> 8.5467489 | D44: =AVERAGE($A44*(($B$16*(1-D$40-$B$18))-$B$20)*(1-Inputs!$B$32)/$B$22+$B$25,($K$11*($B$16*(1-D$40-$B$18))-$B$26)/$B$22)-Inputs!$B$27 -> 7.2765349 | E44: =AVERAGE($A44*(($B$16*(1-E$40-$B$18))-$B$20)*(1-Inputs!$B$32)/$B$22+$B$25,($K$11*($B$16*(1-E$40-$B$18))-$B$26)/$B$22)-Inputs!$B$27 -> 5.3712139 | F44: =AVERAGE($A44*(($B$16*(1-F$40-$B$18))-$B$20)*(1-Inputs!$B$32)/$B$22+$B$25,($K$11*($B$16*(1-F$40-$B$18))-$B$26)/$B$22)-Inputs!$B$27 -> 3.7834464 | G44: =AVERAGE($A44*(($B$16*(1-G$40-$B$18))-$B$20)*(1-Inputs!$B$32)/$B$22+$B$25,($K$11*($B$16*(1-G$40-$B$18))-$B$26)/$B$22)-Inputs!$B$27 -> 2.1956789
A45: 17 | B45: =AVERAGE($A45*(($B$16*(1-B$40-$B$18))-$B$20)*(1-Inputs!$B$32)/$B$22+$B$25,($K$11*($B$16*(1-B$40-$B$18))-$B$26)/$B$22)-Inputs!$B$27 -> 10.491234 | C45: =AVERAGE($A45*(($B$16*(1-C$40-$B$18))-$B$20)*(1-Inputs!$B$32)/$B$22+$B$25,($K$11*($B$16*(1-C$40-$B$18))-$B$26)/$B$22)-Inputs!$B$27 -> 8.8477686 | D45: =AVERAGE($A45*(($B$16*(1-D$40-$B$18))-$B$20)*(1-Inputs!$B$32)/$B$22+$B$25,($K$11*($B$16*(1-D$40-$B$18))-$B$26)/$B$22)-Inputs!$B$27 -> 7.5329964 | E45: =AVERAGE($A45*(($B$16*(1-E$40-$B$18))-$B$20)*(1-Inputs!$B$32)/$B$22+$B$25,($K$11*($B$16*(1-E$40-$B$18))-$B$26)/$B$22)-Inputs!$B$27 -> 5.5608381 | F45: =AVERAGE($A45*(($B$16*(1-F$40-$B$18))-$B$20)*(1-Inputs!$B$32)/$B$22+$B$25,($K$11*($B$16*(1-F$40-$B$18))-$B$26)/$B$22)-Inputs!$B$27 -> 3.9173728 | G45: =AVERAGE($A45*(($B$16*(1-G$40-$B$18))-$B$20)*(1-Inputs!$B$32)/$B$22+$B$25,($K$11*($B$16*(1-G$40-$B$18))-$B$26)/$B$22)-Inputs!$B$27 -> 2.2739075
...
